Workbook

Sheet Cover
A1: Dollarama Inc. (TSX: DOL) — Financial Model & Valuation
A2: Prepared by Munzeleen Sarwar • October 2026 • Educational portfolio project — not investment advice
A5: CONTENTS
A6: Historicals & Ratios | B6: FY2022–FY2026 financials from Dollarama's filed statements (via StockAnalysis.com) with computed ratios
A7: Forecast & 3-Statement | B7: Integrated income statement, condensed balance sheet and cash-flow summary, FY2027E–FY2031E, driven by explicit assumptions
A8: DCF & Sensitivity | B8: Free-cash-flow-to-firm DCF, WACC build, sensitivity grid and valuation football field
A9: Comps | B9: Trading comparables: North American value retail and Canadian food/convenience retail, October 2026
A11: KEY OUTPUTS (live from DCF sheet)
A12: DCF implied share price (CAD) | B12: ='DCF & Sensitivity'!B31
A13: Share price, 21 Oct 2026 close (CAD) | B13: 204.59
A14: Implied upside / (downside) | B14: ='DCF & Sensitivity'!B32
A15: Recommendation implied by base case | B15: HOLD — a high-quality compounder priced at a premium to base-case value
A17: METHOD NOTES
A18: Leases (IFRS 16) | B18: FCFF is calculated before lease payments; total debt in the bridge includes lease liabilities (FY2026: $5,396M incl. $2,771M leases)
A19: WACC inputs | B19: Risk-free rate, beta and equity risk premium are stated assumptions on the DCF sheet (beta is an analyst assumption for a defensive retailer, not a fetched figure)
A20: Equity base | B20: Dollarama's book equity is small (and was negative in FY2022–23) because of large buybacks — ROE is not meaningful and is excluded; ROA and margins are used instead
A21: Data check | B21: All historical totals are as reported by the data source; check Dollarama's SEDAR+ filings before any investment use

Sheet Historicals & Ratios
A1: Dollarama — Historical Financials & Ratios (CAD millions, fiscal years ending late Jan / early Feb)
B3: FY 2022 | C3: FY 2023 | D3: FY 2024 | E3: FY 2025 | F3: FY 2026
A4: INCOME STATEMENT
A5: Revenue | B5: 4331 | C5: 5053 | D5: 5867 | E5: 6413 | F5: 7256
A6: Cost of Revenue | B6: 2282 | C6: 2702 | D6: 3254 | E6: 3519 | F6: 3987
A7: Gross Profit | B7: 2049 | C7: 2351 | D7: 2613 | E7: 2894 | F7: 3269
A8: Selling, General & Admin | B8: 764.06 | C8: 873.06 | D8: 844.87 | E8: 930.17 | F8: 1093
A9: Operating Expenses (total) | B9: 1062 | C9: 1205 | D9: 1193 | E9: 1313 | F9: 1522
A10: Operating Income (EBIT) | B10: 986.95 | C10: 1146 | D10: 1420 | E10: 1581 | F10: 1746
A11: Interest Expense | B11: -91.22 | C11: -126.83 | D11: -167.22 | E11: -187.45 | F11: -204.12
A12: Pretax Income | B12: 893.4 | C12: 1076 | D12: 1351 | E12: 1547 | F12: 1764
A13: Income Tax Expense | B13: 230.23 | C13: 274.24 | D13: 340.42 | E13: 378.35 | F13: 454.75
A14: Net Income | B14: 663.17 | C14: 801.86 | D14: 1010 | E14: 1169 | F14: 1309
A15: EBITDA (as reported by source) | B15: 1071 | C15: 1239 | D15: 1524 | E15: 1697 | F15: 1851
A16: EPS Diluted (CAD) | B16: 2.18 | C16: 2.76 | D16: 3.56 | E16: 4.16 | F16: 4.73
A17: Shares Outstanding Diluted (M) | B17: 304 | C17: 291 | D17: 284 | E17: 281 | F17: 277
A19: BALANCE SHEET
A20: Cash & Short-Term Investments | B20: 71.06 | C20: 101.26 | D20: 315.9 | E20: 135.05 | F20: 340.49
A21: Inventory | B21: 590.93 | C21: 957.17 | D21: 916.81 | E21: 921.1 | F21: 1103
A22: Total Current Assets | B22: 717.37 | C22: 1157 | D22: 1309 | E22: 1201 | F22: 1522
A23: Property, Plant & Equipment (incl. ROU as aggregated) | B23: 2242 | C23: 2503 | D23: 2740 | E23: 3156 | F23: 3656
A24: Total Assets | B24: 4064 | C24: 4820 | D24: 5264 | E24: 6483 | F24: 7558
A25: Total Current Liabilities | B25: 911.89 | C25: 1163 | D25: 677.85 | E25: 1014 | F25: 1348
A26: Long-Term Debt | B26: 1539 | C26: 1742 | D26: 2243 | E26: 2009 | F26: 2227
A27: Long-Term Leases | B27: 1527 | C27: 1742 | D27: 1835 | E27: 2148 | F27: 2393
A28: Total Liabilities | B28: 4130 | C28: 4791 | D28: 4883 | E28: 5294 | F28: 6102
A29: Shareholders' Equity | B29: -66.03 | C29: 28.41 | D29: 380.85 | E29: 1188 | F29: 1456
A30: Shares Outstanding (M, period end) | B30: 292.81 | C30: 284.51 | D30: 278.76 | E30: 277.03 | F30: 272.73
A32: CASH FLOW
A33: Depreciation & Amortization | B33: 277.5 | C33: 309.6 | D33: 342.54 | E33: 385.08 | F33: 433.58
A34: Operating Cash Flow | B34: 1159 | C34: 869.04 | D34: 1531 | E34: 1644 | F34: 1761
A35: Capital Expenditures | B35: -136.77 | C35: -134.05 | D35: -252.67 | E35: -212.83 | F35: -248.75
A36: Free Cash Flow | B36: 1022 | C36: 734.99 | D36: 1278 | E36: 1431 | F36: 1512
A37: Lease Payments | B37: -229.58 | C37: -253.57 | D37: -284.84 | E37: -317.83 | F37: -390.33
A38: Repurchase of Common Stock (buybacks) | B38: -1060 | C38: -689 | D38: -655.87 | E38: -1091 | F38: -864.38
A39: Common Dividends Paid | B39: -60.46 | C39: -62.98 | D39: -76.13 | E39: -97.24 | F39: -113.2
A41: COMPUTED RATIOS
A42: Gross margin | B42: =B7/B5 | C42: =C7/C5 | D42: =D7/D5 | E42: =E7/E5 | F42: =F7/F5
A43: Operating (EBIT) margin | B43: =B10/B5 | C43: =C10/C5 | D43: =D10/D5 | E43: =E10/E5 | F43: =F10/F5
A44: Net margin | B44: =B14/B5 | C44: =C14/C5 | D44: =D14/D5 | E44: =E14/E5 | F44: =F14/F5
...

Sheet Forecast & 3-Statement
A1: Dollarama — Integrated Forecast (CAD millions unless noted). Yellow cells are assumptions; everything else is a formula.
B3: FY 2026A | C3: FY 2027E | D3: FY 2028E | E3: FY 2029E | F3: FY 2030E | G3: FY 2031E
A4: DRIVERS & ASSUMPTIONS
A5: Revenue growth | C5: 0.13 | D5: 0.1 | E5: 0.085 | F5: 0.075 | G5: 0.065
A6: Gross margin | B6: 0.4505237 | C6: 0.45 | D6: 0.45 | E6: 0.45 | F6: 0.45 | G6: 0.45
A7: SG&A (% of revenue) | B7: 0.15063396 | C7: 0.15 | D7: 0.15 | E7: 0.149 | F7: 0.149 | G7: 0.148
A8: D&A (% of revenue) | B8: 0.059123484 | C8: 0.06 | D8: 0.06 | E8: 0.06 | F8: 0.06 | G8: 0.06
A9: Capex (% of revenue) | B9: 0.034281974 | C9: 0.035 | D9: 0.035 | E9: 0.035 | F9: 0.035 | G9: 0.035
A10: Operating current assets (% of revenue) | B10: 0.16283214 | C10: 0.16283214 | D10: 0.16283214 | E10: 0.16283214 | F10: 0.16283214 | G10: 0.16283214
A11: Operating current liabilities (% of revenue) | B11: 0.078814774 | C11: 0.078814774 | D11: 0.078814774 | E11: 0.078814774 | F11: 0.078814774 | G11: 0.078814774
A12: PP&E/ROU additions from leases (% of revenue) | C12: 0.045 | D12: 0.045 | E12: 0.045 | F12: 0.045 | G12: 0.045
A13: Tax rate | B13: 0.2578 | C13: 0.258 | D13: 0.258 | E13: 0.258 | F13: 0.258 | G13: 0.258
A14: Interest expense ($M) | B14: 204.12 | C14: 215 | D14: 220 | E14: 225 | F14: 230 | G14: 235
A15: Equity & other income ($M) | B15: 222.12 | C15: 200 | D15: 205 | E15: 210 | F15: 215 | G15: 220
A16: Dividend payout (% of net income) | B16: 0.086478228 | C16: 0.09 | D16: 0.09 | E16: 0.09 | F16: 0.09 | G16: 0.09
A17: Share buybacks ($M per year) | B17: 864.38 | C17: 900 | D17: 900 | E17: 900 | F17: 900 | G17: 900
A18: Lease liabilities growth | C18: 0.05 | D18: 0.05 | E18: 0.05 | F18: 0.05 | G18: 0.05
A19: Share count change (buyback effect) | C19: -0.012 | D19: -0.012 | E19: -0.012 | F19: -0.012 | G19: -0.012
A21: INCOME STATEMENT
A22: Revenue | B22: 7256 | C22: =B22*(1+C5) | D22: =C22*(1+D5) | E22: =D22*(1+E5) | F22: =E22*(1+F5) | G22: =F22*(1+G5)
A23: Cost of Revenue | B23: 3987 | C23: =C22*(1-C6) | D23: =D22*(1-D6) | E23: =E22*(1-E6) | F23: =F22*(1-F6) | G23: =G22*(1-G6)
A24: Gross Profit | B24: 3269 | C24: =C22-C23 | D24: =D22-D23 | E24: =E22-E23 | F24: =F22-F23 | G24: =G22-G23
A25: SG&A | B25: 1093 | C25: =C22*C7 | D25: =D22*D7 | E25: =E22*E7 | F25: =F22*F7 | G25: =G22*G7
A26: Depreciation & Amortization | B26: 429 | C26: =C22*C8 | D26: =D22*D8 | E26: =E22*E8 | F26: =F22*F8 | G26: =G22*G8
A27: Operating Income (EBIT) | B27: 1746 | C27: =C24-C25-C26 | D27: =D24-D25-D26 | E27: =E24-E25-E26 | F27: =F24-F25-F26 | G27: =G24-G25-G26
A28: Interest Expense | B28: 204.12 | C28: =C14 | D28: =D14 | E28: =E14 | F28: =F14 | G28: =G14
A29: Equity & Other Income | B29: 222.12 | C29: =C15 | D29: =D15 | E29: =E15 | F29: =F15 | G29: =G15
A30: Pretax Income | B30: 1764 | C30: =C27-C28+C29 | D30: =D27-D28+D29 | E30: =E27-E28+E29 | F30: =F27-F28+F29 | G30: =G27-G28+G29
A31: Income Tax | B31: 454.75 | C31: =C30*C13 | D31: =D30*D13 | E31: =E30*E13 | F31: =F30*F13 | G31: =G30*G13
A32: Net Income | B32: 1309 | C32: =C30-C31 | D32: =D30-D31 | E32: =E30-E31 | F32: =F30-F31 | G32: =G30-G31
A33: EPS Diluted (CAD) | B33: 4.73 | C33: =C32/C51 | D33: =D32/D51 | E33: =E32/E51 | F33: =F32/F51 | G33: =G32/G51
A34: EBIT Margin | B34: =B27/B22 | C34: =C27/C22 | D34: =D27/D22 | E34: =E27/E22 | F34: =F27/F22 | G34: =G27/G22
A35: Net Margin | B35: =B32/B22 | C35: =C32/C22 | D35: =D32/D22 | E35: =E32/E22 | F35: =F32/F22 | G35: =G32/G22
A37: BALANCE SHEET (condensed, integrated)
A38: Cash & Short-Term Investments (plug) | B38: 340.49 | C38: =C49-C39-C40-C41 | D38: =D49-D39-D40-D41 | E38: =E49-E39-E40-E41 | F38: =F49-F39-F40-F41 | G38: =G49-G39-G40-G41
A39: Operating Current Assets | B39: 1181.51 | C39: =C22*C10 | D39: =D22*D10 | E39: =E22*E10 | F39: =F22*F10 | G39: =G22*G10
A40: Net PP&E and Right-of-Use Assets | B40: 3656 | C40: =B40+C22*C9+C22*C12-C26 | D40: =C40+D22*D9+D22*D12-D26 | E40: =D40+E22*E9+E22*E12-E26 | F40: =E40+F22*F9+F22*F12-F26 | G40: =F40+G22*G9+G22*G12-G26
A41: Goodwill & Other Long-Term Assets | B41: 2380 | C41: =B41 | D41: =C41 | E41: =D41 | F41: =E41 | G41: =F41
A42: Total Assets | B42: 7558 | C42: =C38+C39+C40+C41 | D42: =D38+D39+D40+D41 | E42: =E38+E39+E40+E41 | F42: =F38+F39+F40+F41 | G42: =G38+G39+G40+G41
A43: Operating Current Liabilities | B43: 571.88 | C43: =C22*C11 | D43: =D22*D11 | E43: =E22*E11 | F43: =F22*F11 | G43: =G22*G11
...

Sheet DCF & Sensitivity
A1: Dollarama — DCF Valuation (FCFF, leases treated as debt)
A3: WACC BUILD — inputs are stated assumptions (yellow)
A4: Risk-free rate (GoC 10Y, assumption) | B4: 0.034
A5: Beta (analyst assumption — defensive retailer) | B5: 0.6
A6: Equity risk premium (assumption) | B6: 0.05
A7: Cost of equity (CAPM) | B7: =B4+B5*B6
A8: Pre-tax cost of debt (assumption) | B8: 0.043
A9: Tax rate | B9: 0.258
A10: After-tax cost of debt | B10: =B8*(1-B9)
A11: Market value of equity ($M, Oct 2026) | B11: 54906
A12: Total debt incl. leases ($M, FY2026) | B12: 5396
A13: Weight of equity | B13: =B11/(B11+B12)
A14: Weight of debt | B14: =B12/(B11+B12)
A15: WACC | B15: =B13*B7+B14*B10
A17: DCF | C17: FY 2027E | D17: FY 2028E | E17: FY 2029E | F17: FY 2030E | G17: FY 2031E
A18: Free Cash Flow to Firm (EBIT(1-t) + D&A - Capex - ΔWC) | C18: =('Forecast & 3-Statement'!C27*(1-'Forecast & 3-Statement'!C13)+'Forecast & 3-Statement'!C26+'Forecast & 3-Statement'!C58+'Forecast & 3-Statement'!C56) | D18: =('Forecast & 3-Statement'!D27*(1-'Forecast & 3-Statement'!D13)+'Forecast & 3-Statement'!D26+'Forecast & 3-Statement'!D58+'Forecast & 3-Statement'!D56) | E18: =('Forecast & 3-Statement'!E27*(1-'Forecast & 3-Statement'!E13)+'Forecast & 3-Statement'!E26+'Forecast & 3-Statement'!E58+'Forecast & 3-Statement'!E56) | F18: =('Forecast & 3-Statement'!F27*(1-'Forecast & 3-Statement'!F13)+'Forecast & 3-Statement'!F26+'Forecast & 3-Statement'!F58+'Forecast & 3-Statement'!F56) | G18: =('Forecast & 3-Statement'!G27*(1-'Forecast & 3-Statement'!G13)+'Forecast & 3-Statement'!G26+'Forecast & 3-Statement'!G58+'Forecast & 3-Statement'!G56)
A19: Discount years | C19: 1 | D19: 2 | E19: 3 | F19: 4 | G19: 5
A20: Discount factor | C20: =1/(1+$B15)^C19 | D20: =1/(1+$B15)^D19 | E20: =1/(1+$B15)^E19 | F20: =1/(1+$B15)^F19 | G20: =1/(1+$B15)^G19
A21: PV of FCFF | C21: =C18*C20 | D21: =D18*D20 | E21: =E18*E20 | F21: =F18*F20 | G21: =G18*G20
A23: PV of FCFF FY2027E–FY2031E | B23: =SUM(C21:G21)
A24: Terminal growth rate (assumption) | B24: 0.025
A25: Terminal value | B25: =G18*(1+B24)/(B15-B24)
A26: PV of terminal value | B26: =B25*G20
A27: Enterprise value | B27: =B23+B26
A28: Less: net debt incl. leases (FY2026 total debt 5,396 - cash 340) | B28: -5056
A29: Equity value | B29: =B27+B28
A30: Shares outstanding (M) | B30: 272.73
A31: Implied share price (CAD) | B31: =B29*1000000/(B30*1000000)
A32: Implied upside/(downside) vs $204.59 | B32: =B31/204.59-1
A34: SENSITIVITY — Implied share price (CAD): WACC (rows) vs terminal growth (columns)
A35: WACC \ g | B35: 0.015 | C35: 0.02 | D35: 0.025 | E35: 0.03 | F35: 0.035
A36: 0.051 | B36: =(C18/(1+0.051)^1+D18/(1+0.051)^2+E18/(1+0.051)^3+F18/(1+0.051)^4+G18/(1+0.051)^5+(G18*(1+0.015)/(0.051-0.015))/(1+0.051)^5-5056)/272.73 | C36: =(C18/(1+0.051)^1+D18/(1+0.051)^2+E18/(1+0.051)^3+F18/(1+0.051)^4+G18/(1+0.051)^5+(G18*(1+0.02)/(0.051-0.02))/(1+0.051)^5-5056)/272.73 | D36: =(C18/(1+0.051)^1+D18/(1+0.051)^2+E18/(1+0.051)^3+F18/(1+0.051)^4+G18/(1+0.051)^5+(G18*(1+0.025)/(0.051-0.025))/(1+0.051)^5-5056)/272.73 | E36: =(C18/(1+0.051)^1+D18/(1+0.051)^2+E18/(1+0.051)^3+F18/(1+0.051)^4+G18/(1+0.051)^5+(G18*(1+0.03)/(0.051-0.03))/(1+0.051)^5-5056)/272.73 | F36: =(C18/(1+0.051)^1+D18/(1+0.051)^2+E18/(1+0.051)^3+F18/(1+0.051)^4+G18/(1+0.051)^5+(G18*(1+0.035)/(0.051-0.035))/(1+0.051)^5-5056)/272.73
A37: 0.056 | B37: =(C18/(1+0.056)^1+D18/(1+0.056)^2+E18/(1+0.056)^3+F18/(1+0.056)^4+G18/(1+0.056)^5+(G18*(1+0.015)/(0.056-0.015))/(1+0.056)^5-5056)/272.73 | C37: =(C18/(1+0.056)^1+D18/(1+0.056)^2+E18/(1+0.056)^3+F18/(1+0.056)^4+G18/(1+0.056)^5+(G18*(1+0.02)/(0.056-0.02))/(1+0.056)^5-5056)/272.73 | D37: =(C18/(1+0.056)^1+D18/(1+0.056)^2+E18/(1+0.056)^3+F18/(1+0.056)^4+G18/(1+0.056)^5+(G18*(1+0.025)/(0.056-0.025))/(1+0.056)^5-5056)/272.73 | E37: =(C18/(1+0.056)^1+D18/(1+0.056)^2+E18/(1+0.056)^3+F18/(1+0.056)^4+G18/(1+0.056)^5+(G18*(1+0.03)/(0.056-0.03))/(1+0.056)^5-5056)/272.73 | F37: =(C18/(1+0.056)^1+D18/(1+0.056)^2+E18/(1+0.056)^3+F18/(1+0.056)^4+G18/(1+0.056)^5+(G18*(1+0.035)/(0.056-0.035))/(1+0.056)^5-5056)/272.73
A38: 0.061 | B38: =(C18/(1+0.061)^1+D18/(1+0.061)^2+E18/(1+0.061)^3+F18/(1+0.061)^4+G18/(1+0.061)^5+(G18*(1+0.015)/(0.061-0.015))/(1+0.061)^5-5056)/272.73 | C38: =(C18/(1+0.061)^1+D18/(1+0.061)^2+E18/(1+0.061)^3+F18/(1+0.061)^4+G18/(1+0.061)^5+(G18*(1+0.02)/(0.061-0.02))/(1+0.061)^5-5056)/272.73 | D38: =(C18/(1+0.061)^1+D18/(1+0.061)^2+E18/(1+0.061)^3+F18/(1+0.061)^4+G18/(1+0.061)^5+(G18*(1+0.025)/(0.061-0.025))/(1+0.061)^5-5056)/272.73 | E38: =(C18/(1+0.061)^1+D18/(1+0.061)^2+E18/(1+0.061)^3+F18/(1+0.061)^4+G18/(1+0.061)^5+(G18*(1+0.03)/(0.061-0.03))/(1+0.061)^5-5056)/272.73 | F38: =(C18/(1+0.061)^1+D18/(1+0.061)^2+E18/(1+0.061)^3+F18/(1+0.061)^4+G18/(1+0.061)^5+(G18*(1+0.035)/(0.061-0.035))/(1+0.061)^5-5056)/272.73
A39: 0.066 | B39: =(C18/(1+0.066)^1+D18/(1+0.066)^2+E18/(1+0.066)^3+F18/(1+0.066)^4+G18/(1+0.066)^5+(G18*(1+0.015)/(0.066-0.015))/(1+0.066)^5-5056)/272.73 | C39: =(C18/(1+0.066)^1+D18/(1+0.066)^2+E18/(1+0.066)^3+F18/(1+0.066)^4+G18/(1+0.066)^5+(G18*(1+0.02)/(0.066-0.02))/(1+0.066)^5-5056)/272.73 | D39: =(C18/(1+0.066)^1+D18/(1+0.066)^2+E18/(1+0.066)^3+F18/(1+0.066)^4+G18/(1+0.066)^5+(G18*(1+0.025)/(0.066-0.025))/(1+0.066)^5-5056)/272.73 | E39: =(C18/(1+0.066)^1+D18/(1+0.066)^2+E18/(1+0.066)^3+F18/(1+0.066)^4+G18/(1+0.066)^5+(G18*(1+0.03)/(0.066-0.03))/(1+0.066)^5-5056)/272.73 | F39: =(C18/(1+0.066)^1+D18/(1+0.066)^2+E18/(1+0.066)^3+F18/(1+0.066)^4+G18/(1+0.066)^5+(G18*(1+0.035)/(0.066-0.035))/(1+0.066)^5-5056)/272.73
A40: 0.071 | B40: =(C18/(1+0.071)^1+D18/(1+0.071)^2+E18/(1+0.071)^3+F18/(1+0.071)^4+G18/(1+0.071)^5+(G18*(1+0.015)/(0.071-0.015))/(1+0.071)^5-5056)/272.73 | C40: =(C18/(1+0.071)^1+D18/(1+0.071)^2+E18/(1+0.071)^3+F18/(1+0.071)^4+G18/(1+0.071)^5+(G18*(1+0.02)/(0.071-0.02))/(1+0.071)^5-5056)/272.73 | D40: =(C18/(1+0.071)^1+D18/(1+0.071)^2+E18/(1+0.071)^3+F18/(1+0.071)^4+G18/(1+0.071)^5+(G18*(1+0.025)/(0.071-0.025))/(1+0.071)^5-5056)/272.73 | E40: =(C18/(1+0.071)^1+D18/(1+0.071)^2+E18/(1+0.071)^3+F18/(1+0.071)^4+G18/(1+0.071)^5+(G18*(1+0.03)/(0.071-0.03))/(1+0.071)^5-5056)/272.73 | F40: =(C18/(1+0.071)^1+D18/(1+0.071)^2+E18/(1+0.071)^3+F18/(1+0.071)^4+G18/(1+0.071)^5+(G18*(1+0.035)/(0.071-0.035))/(1+0.071)^5-5056)/272.73
A42: FOOTBALL FIELD (CAD per share)
A43: DCF — sensitivity range (WACC 5.6–6.6%, g 2.0–3.0%) | B43: =C39 | C43: =E37
A44: DCF — base case | B44: =B31 | C44: =B31
A45: 52-week trading range (Oct 2026) | B45: 163.25 | C45: 209.96
...

Sheet Comps
A1: Trading Comparables — October 2026 (TTM; US peers in USD — ratios are currency-neutral)
A3: Company | B3: P/E | C3: Forward P/E | D3: P/S | E3: P/FCF | F3: Gross Margin | G3: Operating Margin | H3: Net Margin | I3: Revenue Growth | J3: Dividend Yield
A4: Dollarama (TSX: DOL) | B4: 41.05 | C4: 38.28 | D4: 6.96 | E4: 33.8 | F4: 0.4469 | G4: 0.2285 | H4: 0.1732 | I4: 0.1786 | J4: 0.0023
A5: Dollar General (NYSE: DG) | B5: 17.15 | C5: 16.53 | D5: 0.67 | E5: 14.5 | F5: 0.3116 | G5: 0.0572 | H5: 0.039 | I5: 0.0477 | J5: 0.0179
A6: Dollar Tree (NASDAQ: DLTR) | B6: 15.39 | C6: 18.24 | D6: 1.17 | E6: 11.9 | F6: 0.3718 | G6: 0.0903 | H6: 0.0804 | I6: 0.0818
A7: Five Below (NASDAQ: FIVE) | B7: 20.12 | C7: 22.04 | D7: 2.32 | E7: 20.59 | F7: 0.3758 | G7: 0.1167 | H7: 0.1165 | I7: 0.2556
A8: Loblaw (TSX: L) | B8: 28.86 | C8: 25.61 | D8: 1.21 | E8: 14.93 | F8: 0.3137 | G8: 0.0718 | H8: 0.0429 | I8: 0.0675 | J8: 0.0091
A9: Metro (TSX: MRU) | B9: 22.79 | C9: 18.64 | D9: 0.89 | E9: 16.77 | F9: 0.1946 | G9: 0.0625 | H9: 0.04 | I9: 0.0294 | J9: 0.017
A10: Couche-Tard (TSX: ATD) | B10: 17.25 | C10: 18.13 | D10: 0.68 | E10: 14.82 | F10: 0.1824 | G10: 0.0588 | H10: 0.0394 | I10: 0.1243 | J10: 0.0103
A11: Peer median (excl. Dollarama) | B11: =MEDIAN(B5:B10) | C11: =MEDIAN(C5:C10) | D11: =MEDIAN(D5:D10) | E11: =MEDIAN(E5:E10) | F11: =MEDIAN(F5:F10) | G11: =MEDIAN(G5:G10) | H11: =MEDIAN(H5:H10) | I11: =MEDIAN(I5:I10) | J11: =MEDIAN(J5:J10)
A13: Read: Dollarama has the group's best margins and among its fastest growth — and by far its highest multiples. The investment question is whether the quality justifies a P/E roughly double the peer median.
